<?xml version="1.0"?>
<!-- Basic URDF components for PhantomX Pincher Arm-->
<robot xmlns:xacro="http://ros.org/wiki/xacro">
  <xacro:property name="M_PI" value="3.14159"/>

  <xacro:macro name="pincher_base" params="parent name *origin">
    <joint name="${name}_joint" type="fixed">
      <xacro:insert_block name="origin"/>
      <parent link="${parent}"/>
      <child link="${name}_link"/>
    </joint>

    <link name="${name}_link">
      <!-- TODO: This inertial field needs doesn't contain reliable data!! -->
      <inertial>
        <mass value="0.055"/>
        <origin xyz="0 0 0"/>
        <inertia ixx="0.000017012" ixy="0.0" ixz="0.0"
                 iyy="0.000013258" iyz="0.0"
                 izz="0.000009483"/>
      </inertial>

      <visual>
        <origin xyz="0 0 0" rpy="0 0 0"/>
        <geometry>
          <mesh filename="package://phantomx_pincher_arm_description/meshes/PincherBase.stl" scale="1.0 1.0 1.0"/>
        </geometry>
        <material name="Black"/>
      </visual>

      <collision>
        <origin xyz="0 0 0" rpy="0 0 0"/>
        <geometry>
          <mesh filename="package://phantomx_pincher_arm_description/meshes/PincherBase.stl" scale="1.0 1.0 1.0"/>
        </geometry>
      </collision>
    </link>

    <gazebo reference="${name}_link">
      <material>Gazebo/Black</material>
      <gravity>true</gravity>
    </gazebo>
  </xacro:macro>

  <xacro:macro name="bracket_F2_revolute" params="parent name color llimit ulimit vlimit *origin">
    <joint name="${name}_joint" type="revolute">
      <xacro:insert_block name="origin"/>
      <axis xyz="0 0 1"/>
      <limit effort="6" velocity="${vlimit}" lower="${llimit}" upper="${ulimit}"/>
      <dynamics friction="0.13"/>
      <parent link="${parent}"/>
      <child link="${name}_link"/>
    </joint>

    <link name="${name}_link">
      <!-- TODO: This inertial field needs doesn't contain reliable data!! -->
      <inertial>
        <mass value="0.008"/>
        <origin xyz="0 0 0"/>
        <inertia ixx="0.000001" ixy="0.0" ixz="0.0"
                 iyy="0.000001" iyz="0.0"
                 izz="0.000001"/>
      </inertial>

      <visual>
        <origin xyz="0 0 0" rpy="0 0 0"/>
        <geometry>
          <mesh filename="package://phantomx_pincher_arm_description/meshes/F2Bracket.stl" scale="1.0 1.0 1.0"/>
        </geometry>
        <material name="${color}"/>
      </visual>

      <collision>
        <origin xyz="0 0 0" rpy="0 0 0"/>
        <geometry>
          <mesh filename="package://phantomx_pincher_arm_description/meshes/F2Bracket.stl" scale="1.0 1.0 1.0"/>
        </geometry>
      </collision>
    </link>

    <gazebo reference="${name}_link">
      <material>Gazebo/${color}</material>
      <gravity>true</gravity>
    </gazebo>
  </xacro:macro>

  <xacro:macro name="pincher_bicep" params="parent name color llimit ulimit vlimit *origin">
    <joint name="${name}_joint" type="revolute">
      <xacro:insert_block name="origin"/>
      <axis xyz="0 1 0"/>
      <limit effort="6" velocity="${vlimit}" lower="${llimit}" upper="${ulimit}"/>
      <dynamics friction="0.13"/>
      <parent link="${parent}"/>
      <child link="${name}_link"/>
    </joint>

    <link name="${name}_link">
      <!-- TODO: This inertial field needs doesn't contain reliable data!! -->
      <inertial>
        <mass value="0.016"/>
        <origin xyz="0 0 0"/>
        <inertia ixx="0.000001" ixy="0.0" ixz="0.0"
                 iyy="0.000001" iyz="0.0"
                 izz="0.000001"/>
      </inertial>

      <visual>
        <origin xyz=" 0 0 0 " rpy="0 0 0"/>
        <geometry>
          <mesh filename="package://phantomx_pincher_arm_description/meshes/PincherBicep.stl" scale="1.0 1.0 1.0"/>
        </geometry>
        <material name="${color}"/>
      </visual>

      <collision>
        <origin xyz="0.0 0.0 0.0" rpy="0 0 0"/>
        <geometry>
          <mesh filename="package://phantomx_pincher_arm_description/meshes/PincherBicep.stl" scale="1.0 1.0 1.0"/>
        </geometry>
      </collision>
    </link>
    
    <gazebo reference="${name}_link">
      <material>Gazebo/${color}</material>
      <gravity>true</gravity>
    </gazebo>
  </xacro:macro>

  <xacro:macro name="pincher_forearm" params="parent name color llimit ulimit vlimit *origin">
    <joint name="${name}_joint" type="revolute">
      <xacro:insert_block name="origin"/>
      <axis xyz="0 -1 0"/>
      <limit effort="6" velocity="${vlimit}" lower="${llimit}" upper="${ulimit}"/>
      <dynamics friction="0.13"/>
      <parent link="${parent}"/>
      <child link="${name}_link"/>
    </joint>

    <link name="${name}_link">
      <!-- TODO: This inertial field needs doesn't contain reliable data!! -->
      <inertial>
        <mass value="0.016"/>
        <origin xyz="0 0 0"/>
        <inertia ixx="0.000001" ixy="0.0" ixz="0.0"
                 iyy="0.000001" iyz="0.0"
                 izz="0.000001"/>
      </inertial>

      <visual>
        <origin xyz=" 0 0 0 " rpy="0 0 0"/>
        <geometry>
          <mesh filename="package://phantomx_pincher_arm_description/meshes/PincherForeArm.stl" scale="1.0 1.0 1.0"/>
        </geometry>
        <material name="${color}"/>
      </visual>

      <collision>
        <origin xyz="0.0 0.0 0.0" rpy="0 0 0"/>
        <geometry>
          <mesh filename="package://phantomx_pincher_arm_description/meshes/PincherForeArm.stl" scale="1.0 1.0 1.0"/>
        </geometry>
      </collision>
    </link>
    
    <gazebo reference="${name}_link">
      <material>Gazebo/${color}</material>
      <gravity>true</gravity>
    </gazebo>
  </xacro:macro>
  
  <xacro:macro name="pincher_wrist" params="parent name color llimit ulimit vlimit *origin">
    <joint name="${name}_joint" type="revolute">
      <xacro:insert_block name="origin"/>
      <axis xyz="0 -1 0"/>
      <limit effort="6" velocity="${vlimit}" lower="${llimit}" upper="${ulimit}"/>
      <dynamics friction="0.13"/>
      <parent link="${parent}"/>
      <child link="${name}_link"/>
    </joint>

    <link name="${name}_link">
      <!-- TODO: This inertial field needs doesn't contain reliable data!! -->
      <inertial>
        <mass value="0.01"/>
        <origin xyz="0 0 0"/>
        <inertia ixx="0.000001" ixy="0.0" ixz="0.0"
                 iyy="0.000001" iyz="0.0"
                 izz="0.000001"/>
      </inertial>

      <visual>
        <origin xyz=" 0 0 0 " rpy="0 0 0"/>
        <geometry>
          <mesh filename="package://phantomx_pincher_arm_description/meshes/PincherWristGripper.stl" scale="1.0 1.0 1.0"/>
        </geometry>
        <material name="${color}"/>
      </visual>

      <collision>
        <origin xyz="0.0 0.0 0.0" rpy="0 0 0"/>
        <geometry>
          <mesh filename="package://phantomx_pincher_arm_description/meshes/PincherWristGripper.stl" scale="1.0 1.0 1.0"/>
        </geometry>
      </collision>
    </link>
    
    <gazebo reference="${name}_link">
      <material>Gazebo/${color}</material>
      <gravity>true</gravity>
    </gazebo>
  </xacro:macro>
  
  <xacro:macro name="pincher_finger" params="name color *origin">
    <link name="${name}_link">
      <inertial>
        <!-- TODO: This inertial field needs doesn't contain reliable data!! -->
        <mass value="0.01"/>
        <origin xyz="0 0 0"/>
        <inertia ixx="0.000001" ixy="0.0" ixz="0.0"
                 iyy="0.000001" iyz="0.0"
                 izz="0.000001"/>
      </inertial>
      <visual>
        <xacro:insert_block name="origin"/>
        <geometry>
          <mesh filename="package://phantomx_pincher_arm_description/meshes/PincherFinger.stl" scale="1.0 1.0 1.0"/>
        </geometry>
        <material name="${color}"/>
      </visual>
      <collision>
        <xacro:insert_block name="origin"/>
        <geometry>
          <mesh filename="package://phantomx_pincher_arm_description/meshes/PincherFinger.stl" scale="1.0 1.0 1.0"/>
        </geometry>
      </collision>
    </link>
  
    <gazebo reference="${name}_link">
      <material>Gazebo/${color}</material>
      <!--selfCollide>true</selfCollide-->
      <gravity>true</gravity>
    </gazebo>
  </xacro:macro>
</robot>
