<?xml version="1.0"?>
<!-- Arm description for PhantomX Pincher arm -->
<robot name="phantomx_pincher_arm" xmlns:xacro="http://ros.org/wiki/xacro">
  <xacro:include filename="$(find phantomx_pincher_arm_description)/urdf/arm_hardware.xacro"/>

  <!--joints_vlimit pan_llimit pan_ulimit-->
  <xacro:macro name="phantomx_pincher_arm" params="parent color gripper_color *origin">

    <!-- arm base link -->
    <pincher_base parent="${parent}" name="arm_base">
      <xacro:insert_block name="origin"/>
    </pincher_base>
    <bracket_F2_revolute parent="arm_base_link" name="arm_shoulder_pan" color="${color}"
                         vlimit="${joints_vlimit}" llimit="${pan_llimit}" ulimit="${pan_ulimit}">
      <origin xyz="0 0 0.020" rpy="0 0 0"/>
    </bracket_F2_revolute>
    <transmission name="arm_shoulder_pan_transmission">
      <type>transmission_interface/SimpleTransmission</type>
      <joint name="arm_shoulder_pan_joint">
        <hardwareInterface>EffortJointInterface</hardwareInterface>
      </joint>
      <actuator name="arm_shoulder_pan_actuator">
        <hardwareInterface>EffortJointInterface</hardwareInterface>
        <mechanicalReduction>1</mechanicalReduction>
      </actuator>
    </transmission>

    <!-- shoulder lift joint -->
    <pincher_bicep parent="arm_shoulder_pan_link" name="arm_bicep" color="${color}"
                         vlimit="${joints_vlimit}" llimit="${shoulder_llimit}" ulimit="${shoulder_ulimit}">
      <origin xyz="0 0 0.027" rpy="0 0 0"/>
    </pincher_bicep>

    <transmission name="arm_bicep_transmission">
      <type>transmission_interface/SimpleTransmission</type>
      <joint name="arm_bicep_joint">
        <hardwareInterface>EffortJointInterface</hardwareInterface>
      </joint>
      <actuator name="arm_bicep_actuator">
        <hardwareInterface>EffortJointInterface</hardwareInterface>
        <mechanicalReduction>1</mechanicalReduction>
      </actuator>
    </transmission>

    <!-- elbow joint -->
    <pincher_forearm parent="arm_bicep_link" name="arm_forearm" color="${color}"
                         vlimit="${joints_vlimit}" llimit="${elbow_llimit}" ulimit="${elbow_ulimit}">
      <origin xyz="0.0325 0 0.104" rpy="0 0 0"/>
    </pincher_forearm>
   
    <transmission name="arm_forearm_transmission">
      <type>transmission_interface/SimpleTransmission</type>
      <joint name="arm_forearm_joint">
        <hardwareInterface>EffortJointInterface</hardwareInterface>
      </joint>
      <actuator name="arm_forearm_actuator">
        <hardwareInterface>EffortJointInterface</hardwareInterface>
        <mechanicalReduction>1</mechanicalReduction>
      </actuator>
    </transmission>

    <!-- wrist joint -->
    <pincher_wrist parent="arm_forearm_link" name="arm_wrist_flex" color="${color}"
                         vlimit="${joints_vlimit}" llimit="${wrist_llimit}" ulimit="${wrist_ulimit}">
      <origin xyz="0.104 0 0" rpy="0 0 0"/>
    </pincher_wrist>
    <transmission name="arm_wrist_flex_transmission">
      <type>transmission_interface/SimpleTransmission</type>
      <joint name="arm_wrist_flex_joint">
        <hardwareInterface>EffortJointInterface</hardwareInterface>
      </joint>
      <actuator name="arm_wrist_flex_actuator">
        <hardwareInterface>EffortJointInterface</hardwareInterface>
        <mechanicalReduction>1</mechanicalReduction>
      </actuator>
    </transmission>

  <!-- gripper -->
  <xacro:include filename="$(find phantomx_pincher_arm_description)/urdf/phantomx_pincher_gripper.xacro"/>

<!-- gripper_link -->
    <link name="gripper_link"/>
    <joint name="gripper_link_joint" type="revolute">
      <origin xyz="0.110 0 0" rpy="0 0 0"/>
      <parent link="arm_wrist_flex_link"/>
      <child link="gripper_link"/>
      <limit effort="6" velocity="1" lower="-3.14" upper="3.14"/>
      <axis xyz="1 0 0"/>
    </joint>
  <!--gazebo>
      <gripper name="gripper">
        <grasp_check>
          <attach_steps>5</attach_steps>
          <detach_steps>10</detach_steps>
          <min_contact_count>2</min_contact_count>
        </grasp_check>
      </gripper>
      <gripper_link>gripper_active_link</gripper_link>
      <palm_link>gripper_servo_link</palm_link>
  </gazebo-->

  </xacro:macro>

</robot>
